{
	"cacheVersn": 0,
	"data": "[{\"brand\":\"Gmail Single User\",\"category\":\"Email\",\"information\":\"Test is not supported. Please use the following command: !gmail-auth-test. (85)\",\"instance\":\"Gmail Single User_instance_1\"},{\"information\":\"Error in API call [404] - Not Found\\n{\\\"timestamp\\\": \\\"2024-03-08T15:03:38.509770442Z\\\", \\\"status\\\": 404, \\\"error\\\": \\\"Not Found\\\", \\\"message\\\": \\\"No message available\\\", \\\"path\\\": \\\"/ex/jira/rest/api/2/myself\\\"} (85)\",\"instance\":\"Jira V3_instance_1\",\"brand\":\"Jira V3\",\"category\":\"Case Management\"},{\"instance\":\"PrismaCloud v2_instance_1\",\"brand\":\"PrismaCloud v2\",\"category\":\"Network Security\",\"information\":\"Authentication failed. Check that the Server URL parameter is correct and validate your credentials.\\nError in API call [401] - Unauthorized\\n{\\\"message\\\": \\\"invalid_credentials\\\"}[{\\\"severity\\\":\\\"error\\\",\\\"i18nKey\\\":\\\"invalid_credentials\\\"}] (85)\"},{\"category\":\"Analytics \u0026 SIEM\",\"information\":\"Failed to execute test-module command.\\nError:\\nTraceback (most recent call last):\\n  File \\\"\u003cstring\u003e\\\", line 16413, in main\\n  File \\\"\u003cstring\u003e\\\", line 13921, in test_module_command\\n  File \\\"\u003cstring\u003e\\\", line 12600, in offenses_list\\n  File \\\"\u003cstring\u003e\\\", line 12535, in http_request\\n  File \\\"\u003cstring\u003e\\\", line 9343, in _http_request\\n  File \\\"/usr/local/lib/python3.10/site-packages/requests/sessions.py\\\", line 575, in request\\n    prep = self.prepare_request(req)\\n  File \\\"/usr/local/lib/python3.10/site-packages/requests/sessions.py\\\", line 486, in prepare_request\\n    p.prepare(\\n  File \\\"/usr/local/lib/python3.10/site-packages/requests/models.py\\\", line 368, in prepare\\n    self.prepare_url(url, params)\\n  File \\\"/usr/local/lib/python3.10/site-packages/requests/models.py\\\", line 439, in prepare_url\\n    raise MissingSchema(\\nrequests.exceptions.MissingSchema: Invalid URL 'dfgdg/api/siem/offenses': No scheme supplied. Perhaps you meant https://dfgdg/api/siem/offenses?\\n (85)\",\"instance\":\"QRadar v3_instance_1\",\"brand\":\"QRadar v3\"},{\"brand\":\"Rapid7 InsightIDR\",\"category\":\"Analytics \u0026 SIEM\",\"information\":\"Connection error. Check your region. (85)\",\"instance\":\"Rapid7 InsightIDR_instance_1\"},{\"information\":\"Script failed to run: \\nError: [Traceback (most recent call last):\\n   \\n   File \\\"\u003cstring\u003e\\\", line 2951, in \u003cmodule\u003e\\n   File \\\"\u003cstring\u003e\\\", line 2869, in main\\n   File \\\"/usr/local/lib/python3.10/site-packages/splunklib/client.py\\\", line 345, in connect\\n    s.login()\\n   File \\\"/usr/local/lib/python3.10/site-packages/splunklib/binding.py\\\", line 936, in login\\n    response = self.http.post(\\n   File \\\"/usr/local/lib/python3.10/site-packages/splunklib/binding.py\\\", line 1297, in post\\n    return self.request(url, message)\\n   File \\\"/usr/local/lib/python3.10/site-packages/splunklib/binding.py\\\", line 1316, in request\\n    response = self.handler(url, message, **kwargs)\\n   File \\\"\u003cstring\u003e\\\", line 2054, in requests_handler\\n   File \\\"/usr/local/lib/python3.10/site-packages/requests/api.py\\\", line 59, in request\\n    return session.request(method=method, url=url, **kwargs)\\n   File \\\"/usr/local/lib/python3.10/site-packages/requests/sessions.py\\\", line 589, in request\\n    resp = self.send(prep, **send_kwargs)\\n   File \\\"/usr/local/lib/python3.10/site-packages/requests/sessions.py\\\", line 703, in send\\n    r = adapter.send(request, **kwargs)\\n   File \\\"/usr/local/lib/python3.10/site-packages/requests/adapters.py\\\", line 519, in send\\n    raise ConnectionError(e, request=request)\\n requests.exceptions.ConnectionError: HTTPSConnectionPool(host='gfdfgfd', port=8089): Max retries exceeded with url: /services/auth/login (Caused by NameResolutionError(\\\"\u003curllib3.connection.HTTPSConnection object at 0x7fcc170f20b0\u003e: Failed to resolve 'gfdfgfd' ([Errno -2] Name does not resolve)\\\"))\\n] (2604) (2603)\",\"instance\":\"SplunkPy_instance_1\",\"brand\":\"SplunkPy\",\"category\":\"Analytics \u0026 SIEM\"}]",
	"definitionId": "",
	"description": "",
	"detached": false,
	"fromServerVersion": "",
	"id": "XSOAR Health - Failed Integrations Table",
	"itemVersion": "",
	"locked": false,
	"name": "XSOAR Health - Failed Integrations Table",
	"nameLocked": false,
	"packID": "",
	"packName": "",
	"propagationLabels": [
		"all"
	],
	"system": false,
	"tags": null,
	"toServerVersion": "",
	"truncated": false,
	"type": "plain_text",
	"version": -1
}